<?xml version="1.0"?>
<robot name="Cylinder">
    <link name="robot_base">
        <inertial>
            <origin rpy="-1.570796 3.141593 -3.141593" xyz="0.000000 0.000000 0.225000" />
            <inertia izz="0.00049087385212344" iyy="0.00032724923474896" ixx="0.00032724923474896"
                ixy="0.0" ixz="0.0" iyz="0.0" />
            <mass value="0.39269908169875" />
        </inertial>
        <collision name="Cylinder">
            <origin xyz="0.000000 0.000000 0.225000" rpy="-1.570796 3.141593 -3.141593" />
            <geometry>
                <cylinder length="0.05" radius="0.05" />
            </geometry>
        </collision>
        <visual name="Cylinder">
            <origin xyz="0.000000 0.000000 0.225000" rpy="-1.570796 3.141593 -3.141593" />
            <geometry>
                <cylinder length="0.05" radius="0.05" />
            </geometry>
            <material name="robot_base_material">
                <color rgba="0.850000 0.850000 1.000000 1.0" />
            </material>
        </visual>
    </link>
    <joint name="Revolute_joint" type="continuous">
        <axis xyz="0 0 1" />
        <parent link="robot_base" />
        <child link="Cuboid" />
        <origin xyz="0.000000 0.000000 0.225000" rpy="-1.570796 4.014257 3.141593" />
    </joint>
    <link name="Cuboid">
        <inertial>
            <origin rpy="1.570796 3.141593 3.141593" xyz="0.000000 -0.075000 0.050000" />
            <inertia izz="0.0002725" iyy="0.0005" ixx="0.0002725" ixy="0.0" ixz="0.0" iyz="0.0" />
            <mass value="0.3" />
        </inertial>
        <collision name="Cuboid">
            <origin xyz="0.000000 -0.075000 0.050000" rpy="1.570796 3.141593 3.141593" />
            <geometry>
                <box size="0.030000 0.030000 0.150000" />
            </geometry>
        </collision>
        <visual name="Cuboid">
            <origin xyz="0.000000 -0.075000 0.050000" rpy="1.570796 3.141593 3.141593" />
            <geometry>
                <box size="0.030000 0.030000 0.150000" />
            </geometry>
            <material name="Cuboid_material">
                <color rgba="0.850000 0.850000 1.000000 1.0" />
            </material>
        </visual>
    </link>
</robot>