<mujoco>
    <compiler meshdir="asset" texturedir="asset" />
    <statistic extent="1.5" meansize=".05" />

    <option timestep="0.005" jacobian="sparse" />

    <visual>
        <rgba haze="0.15 0.25 0.35 1" />
        <quality shadowsize="4096" />
        <map stiffness="700" shadowscale="0.5" fogstart="10" fogend="15" zfar="40" haze="0.3" />
    </visual>

    <asset>
        <texture type="skybox" builtin="gradient" rgb1="0.3 0.5 0.7" rgb2="0 0 0" width="512"
            height="512" />
        <texture name="texplane" type="2d" builtin="checker" rgb1=".2 .3 .4" rgb2=".1 0.15 0.2"
            width="512" height="512" mark="cross" markrgb=".8 .8 .8" />
        <material name="matplane" reflectance="0.3" texture="texplane" texrepeat="1 1"
            texuniform="true" />
    </asset>

    <default>
        <default class="active_adhesion">
            <!--
        Geoms in the active_adhesion class are "inflated" with a margin of 1cm, but contacts are
        activated only at a depth gap of 1cm, leading to a layer of inactive contacts at a 1cm
        distance from the surface. However the contacts can be used by the adhesion actuator.
      -->
            <geom rgba=".8 .5 .5 1" margin=".01" gap=".01" />
        </default>
    </default>

    <worldbody>
        <body name="swerve_wheel_robot" pos="0 0 .03"
            quat="0.707105 0.0 0.0 -0.707105">
            <freejoint name="space" />
            <geom name="Body" size="0.075 0.075 0.01" pos="0.471 0.044 0.11"
                quat="1.99885e-06 -0.707109 0.707105 -1.22469e-07" type="box" />
            <body name="wheel_cover" pos="0.421 0.094 0.0985"
                quat="-0.707114 8.15729e-07 1.76776e-06 -0.707099">
                <inertial pos="3.8e-05 -1.7e-05 -0.017631" quat="0.5 0.498913 -0.501087 0.499997"
                    mass="0.0194363" diaginertia="1.44277e-05 1.19776e-05 8.2964e-06" />
                <joint name="direction_joint_1" pos="0 0 0" axis="0 0 1" />
                <geom name="wheel_cover" size="0.002813 0.01 0.032659"
                    pos="0.000101 0.020624 -0.040796"
                    quat="-0.707111 -7.61232e-05 0.000118086 0.707103" type="box" />
                <geom size="0.002813 0.01 0.032659" pos="0.000101 -0.020719 -0.040794"
                    quat="-0.707111 -7.61232e-05 0.000118086 0.707103" type="box" />
                <geom size="0.0050005 0.0234385 0.025782" pos="0 1e-06 -0.003548"
                    quat="1.91313e-05 0.707086 1.95935e-05 0.707127" type="box" />
                <body name="magnet_wheel_1" pos="4.9e-05 -4.8e-05 -0.058"
                    quat="2.03842e-05 -2.10902e-05 0.707126 0.707088" >
                    <inertial pos="0 0 0" quat="0.5 0.5 -0.5 0.5" mass="0.0573566"
                        diaginertia="3.49059e-05 2.17547e-05 2.17547e-05" />
                    <joint name="driven_joint_1" pos="0 0 0" axis="0 0 1" />
                    <geom name="magnet_wheel_1" size="0.035 0.015"
                        quat="-1.73205e-07 -5e-07 1 0"
                        type="cylinder" />
                </body>
            </body>
            <body name="wheel_cover_2" pos="0.421002 -0.005998 0.0985"
                quat="-0.707114 8.15729e-07 1.76776e-06 -0.707099">
                <inertial pos="3.8e-05 -1.7e-05 -0.017631" quat="0.5 0.498913 -0.501087 0.499997"
                    mass="0.0194363" diaginertia="1.44277e-05 1.19776e-05 8.2964e-06" />
                <joint name="direction_joint_2" pos="0 0 0" axis="0 0 1" />
                <geom size="0.002813 0.01 0.032659" pos="0.000101 0.020624 -0.040796"
                    quat="-0.707111 -7.61232e-05 0.000118086 0.707103" type="box" />
                <geom size="0.002813 0.01 0.032659" pos="0.000101 -0.020719 -0.040794"
                    quat="-0.707111 -7.61232e-05 0.000118086 0.707103" type="box" />
                <geom size="0.0050005 0.0234385 0.025782" pos="0 1e-06 -0.003548"
                    quat="1.91313e-05 0.707086 1.95935e-05 0.707127" type="box" />
                <body name="magnet_wheel_2" pos="4.9e-05 -4.8e-05 -0.058"
                    quat="2.03842e-05 -2.10902e-05 0.707126 0.707088" >
                    <inertial pos="0 0 0" quat="0 0.707107 0 0.707107" mass="0.0573566"
                        diaginertia="3.49059e-05 2.17547e-05 2.17547e-05" />
                    <joint name="driven_joint_2" pos="0 0 0" axis="0 0 1" />
                    <geom name="magnet_wheel_2" size="0.035 0.015"
                        quat="-1.73205e-07 0 1 0"
                        type="cylinder" />
                </body>
            </body>
            <body name="wheel_cover_3" pos="0.521 0.094001 0.0985"
                quat="-0.707114 8.15729e-07 1.76776e-06 -0.707099">
                <inertial pos="3.8e-05 3e-05 -0.017631" quat="0.5 0.498913 -0.501087 0.499997"
                    mass="0.0194363" diaginertia="1.44277e-05 1.19776e-05 8.2964e-06" />
                <joint name="direction_joint_3" pos="0 0 0" axis="0 0 1" />
                <geom size="0.002813 0.01 0.032659" pos="0.000101 0.020671 -0.040796"
                    quat="-0.707111 -7.61232e-05 0.000118086 0.707103" type="box" />
                <geom size="0.002813 0.01 0.032659" pos="0.000101 -0.020672 -0.040794"
                    quat="-0.707111 -7.61232e-05 0.000118086 0.707103" type="box" />
                <geom size="0.0050005 0.0234385 0.025782" pos="0 4.8e-05 -0.003548"
                    quat="1.91313e-05 0.707086 1.95935e-05 0.707127" type="box" />
                <body name="magnet_wheel_3" pos="0 0 -0.058"
                    quat="2.03842e-05 -2.10902e-05 0.707126 0.707087" >
                    <inertial pos="0 0 0" quat="0 0.707107 0 0.707107" mass="0.0573566"
                        diaginertia="3.49059e-05 2.17547e-05 2.17547e-05" />
                    <joint name="driven_joint_3" pos="0 0 0" axis="0 0 1" />
                    <geom name="magnet_wheel_3" size="0.035 0.015"
                        quat="-1.73205e-07 -5e-07 1 0"
                        type="cylinder" />
                </body>
            </body>
            <body name="wheel_cover_4" pos="0.520999 -0.005998 0.0985"
                quat="-0.707114 8.15729e-07 1.76776e-06 -0.707099">
                <inertial pos="3.8e-05 -1.7e-05 -0.017631" quat="0.5 0.498913 -0.501087 0.499997"
                    mass="0.0194363" diaginertia="1.44277e-05 1.19776e-05 8.2964e-06" />
                <joint name="direction_joint_4" pos="0 0 0" axis="0 0 1" />
                <geom size="0.002813 0.01 0.032659" pos="0.000101 0.020624 -0.040796"
                    quat="-0.707111 -7.61232e-05 0.000118086 0.707103" type="box" />
                <geom size="0.002813 0.01 0.032659" pos="0.000101 -0.020719 -0.040794"
                    quat="-0.707111 -7.61232e-05 0.000118086 0.707103" type="box" />
                <geom size="0.0050005 0.0234385 0.025782" pos="0 1e-06 -0.003548"
                    quat="1.91313e-05 0.707086 1.95935e-05 0.707127" type="box" />
                <body name="magnet_wheel_4" pos="4.9e-05 -4.8e-05 -0.058"
                    quat="2.03842e-05 -2.10902e-05 0.707126 0.707088" >
                    <inertial pos="0 0 0" quat="0 0.707107 0 0.707107" mass="0.0573566"
                        diaginertia="3.49059e-05 2.17547e-05 2.17547e-05" />
                    <joint name="driven_joint_4" pos="0 0 0" axis="0 0 1" />
                    <geom name="magnet_wheel_4" size="0.035 0.015"
                        quat="-1.73205e-07 0 1 0"
                        type="cylinder" />
                </body>
            </body>
        </body>


        <body name="wall" pos="0.7 0 0.5">
            <geom name="wall_geom" type="box" size="0.1 1 0.5" rgba="0.8 0.3 0.3 1" friction="2 0.1 0.01"/>
        </body>

        <light directional="true" diffuse=".4 .4 .4" specular="0.1 0.1 0.1" pos="0 0 5.0"
            dir="0 0 -1" castshadow="false" />
        <light directional="true" diffuse=".6 .6 .6" specular="0.2 0.2 0.2" pos="0 0 4"
            dir="0 0 -1" />


        <geom name="ground" type="plane" size="0 0 1" pos="0 0 0" quat="1 0 0 0"
            material="matplane"
            condim="1" />
        <body mocap="true" pos="-.1 .05 0" zaxis=".5 0 1">
        </body>


    </worldbody>

    <actuator>

        <motor name="space" joint="space" />

        <position name="direction_joint_1" joint="direction_joint_1" kp="0.5" kv="0.01" />
        <velocity name="driven_joint_1" joint="driven_joint_1" kv="0.01" />

        <position name="direction_joint_2" joint="direction_joint_2" kp="0.5" kv="0.01" />
        <velocity name="driven_joint_2" joint="driven_joint_2" kv="0.01" />

        <position name="direction_joint_3" joint="direction_joint_3" kp="0.5" kv="0.01" />
        <velocity name="driven_joint_3" joint="driven_joint_3" kv="0.01" />

        <position name="direction_joint_4" joint="direction_joint_4" kp="0.5" kv="0.01" />
        <velocity name="driven_joint_4" joint="driven_joint_4" kv="0.01" />

        <adhesion name="magnet_wheel_1" body="magnet_wheel_1" ctrlrange="0 1" gain="5"/>
        <adhesion name="magnet_wheel_2" body="magnet_wheel_2" ctrlrange="0 1" gain="5"/>
        <adhesion name="magnet_wheel_3" body="magnet_wheel_3" ctrlrange="0 1" gain="5"/>
        <adhesion name="magnet_wheel_4" body="magnet_wheel_4" ctrlrange="0 1" gain="5"/>

    </actuator>

    <!-- <contact>
        <pair geom1="wall_geom" geom2="magnet_wheel_1" friction="2 2 2" solref="0.005 1"
            solimp="0.9 0.95 0.001" />
        <pair geom1="wall_geom" geom2="magnet_wheel_2" friction="2 2 2" solref="0.005 1"
            solimp="0.9 0.95 0.001" />
        <pair geom1="wall_geom" geom2="magnet_wheel_3" friction="2 2 2" solref="0.005 1"
            solimp="0.9 0.95 0.001" />
        <pair geom1="wall_geom" geom2="magnet_wheel_4" friction="2 2 2" solref="0.005 1"
            solimp="0.9 0.95 0.001" />
    </contact> -->
</mujoco>