<mujoco>
    <!-- <compiler meshdir="asset" texturedir="asset" />
    <statistic extent="1.5" meansize=".05" /> -->
    <compiler autolimits="true" />

    <!-- <option timestep="0.005" jacobian="sparse" /> -->

    <visual>
        <rgba haze="0.15 0.25 0.35 1" />
        <quality shadowsize="4096" />
        <map stiffness="700" shadowscale="0.5" fogstart="10" fogend="15" zfar="40" haze="0.3" />
    </visual>

    <asset>
        <texture type="skybox" builtin="gradient" rgb1="0.3 0.5 0.7" rgb2="0 0 0" width="512"
            height="512" />
        <texture name="texplane" type="2d" builtin="checker" rgb1=".2 .3 .4" rgb2=".1 0.15 0.2"
            width="512" height="512" mark="cross" markrgb=".8 .8 .8" />
        <material name="matplane" reflectance="0.3" texture="texplane" texrepeat="1 1"
            texuniform="true" />
    </asset>


    <worldbody>
        <!-- Model setup -->
        <body name="robot" pos="0 0 .03">
            <freejoint />
            <geom name="Cylinder" size="0.05 0.025" pos="0 0 0.225"
                quat="0.707107 0.707107 -2.44949e-07 0" type="cylinder" />
            <body name="Cuboid" pos="0 0 0.225" quat="-0.640856 -0.640857 0.298836 -0.298836">
                <inertial pos="0 -0.075 0.05" quat="0.707107 0 0 0.707107" mass="0.3"
                    diaginertia="0.0005 0.0002725 0.0002725" />
                <joint name="Revolute_joint" pos="0 0 0" axis="0 0 1" />
                <geom name="Cuboid" size="0.015 0.015 0.075" pos="0 -0.075 0.05"
                    quat="0.707107 -0.707107 -2.44949e-07 0" type="box" />
            </body>
        </body>

        <!-- Light setup -->
        <light directional="true" diffuse=".4 .4 .4" specular="0.1 0.1 0.1" pos="0 0 5.0"
            dir="0 0 -1" castshadow="false" />
        <light directional="true" diffuse=".6 .6 .6" specular="0.2 0.2 0.2" pos="0 0 4" dir="0 0 -1" />

        <!-- Ground setup -->
        <geom name="ground" type="plane" size="0 0 1" pos="0 0 0" quat="1 0 0 0" material="matplane"
            condim="1" />
        <body mocap="true" pos="-.1 .05 0" zaxis=".5 0 1">
        </body>
    </worldbody>


    <!-- Joint control setup -->

    <actuator>
        <position name="joint_position_ctrl" joint="Revolute_joint" kp="1" kv="0.01" />
    </actuator>

    <!-- Torque-based control for the Revolute_joint -->
    <!-- <actuator>
        <motor joint="Revolute_joint" ctrllimited="true" ctrlrange="-1 1" />
    </actuator> -->


</mujoco>