<?xml version="1.0"?>
<robot name="Body">
    <link name="robot_base">
        <inertial>
            <origin rpy="-1.570732 4.614213 -1.658126" xyz="-1.302407 -0.149667 0.124992" />
            <inertia izz="5.6240590621472e-06" iyy="3.9195142741455e-05" ixx="3.9369546794003e-05" iyz="7.21947716711e-11" ixz="1.4883479783928e-09" ixy="-2.7996715150358e-13" />
            <mass value="0.0049999998882413" />
        </inertial>
        <collision name="Body">
            <origin xyz="-1.349835 -0.145640 0.125000" rpy="2.896195 4.712383 -2.983463" />
            <geometry>
                <cylinder radius="0.050000000745058" length="0.20000000298023" />
            </geometry>
        </collision>
        <collision name="Body">
            <origin xyz="-1.175381 -0.133716 0.124975" rpy="-3.141593 3.141593 -2.356194" />
            <geometry>
                <sphere radius="0.025000000372529" />
            </geometry>
        </collision>
        <collision name="Body">
            <origin xyz="-1.200382 -0.158716 0.124975" rpy="2.929281 4.712383 -3.016549" />
            <geometry>
                <sphere radius="0.050000000745058" />
            </geometry>
        </collision>
        <collision name="Body">
            <origin xyz="-1.250191 -0.154358 0.124976" rpy="0.135751 1.570807 0.048483" />
            <geometry>
                <cylinder radius="0.025000000372529" length="0.050000000745058" />
            </geometry>
        </collision>
        <collision name="Body">
            <origin xyz="-1.175382 -0.183716 0.124975" rpy="3.141593 3.141593 2.356195" />
            <geometry>
                <sphere radius="0.025000000372529" />
            </geometry>
        </collision>
        <visual name="Body">
            <origin xyz="-1.349835 -0.145640 0.125000" rpy="2.896195 4.712383 -2.983463" />
            <geometry>
                <cylinder radius="0.050000000745058" length="0.20000000298023" />
            </geometry>
            <material name="robot_base_material">
                <color rgba="0.720000 0.000000 0.000000 1.0" />
            </material>
        </visual>
        <visual name="Body">
            <origin xyz="-1.175381 -0.133716 0.124975" rpy="-3.141593 3.141593 -2.356194" />
            <geometry>
                <sphere radius="0.025000000372529" />
            </geometry>
            <material name="robot_base_material">
                <color rgba="0.850000 0.850000 0.850000 1.0" />
            </material>
        </visual>
        <visual name="Body">
            <origin xyz="-1.200382 -0.158716 0.124975" rpy="2.929281 4.712383 -3.016549" />
            <geometry>
                <sphere radius="0.050000000745058" />
            </geometry>
            <material name="robot_base_material">
                <color rgba="0.712421 0.007579 0.007579 1.0" />
            </material>
        </visual>
        <visual name="Body">
            <origin xyz="-1.250191 -0.154358 0.124976" rpy="0.135751 1.570807 0.048483" />
            <geometry>
                <cylinder radius="0.025000000372529" length="0.050000000745058" />
            </geometry>
            <material name="robot_base_material">
                <color rgba="0.730000 0.000000 0.000000 1.0" />
            </material>
        </visual>
        <visual name="Body">
            <origin xyz="-1.175382 -0.183716 0.124975" rpy="3.141593 3.141593 2.356195" />
            <geometry>
                <sphere radius="0.025000000372529" />
            </geometry>
            <material name="robot_base_material">
                <color rgba="0.850000 0.850000 0.850000 1.0" />
            </material>
        </visual>
        <visual name="leftFinger_visible">
            <origin xyz="-1.167511 -0.143113 0.084538" rpy="-0.698133 3.141593 -1.570796" />
            <geometry>
                <mesh filename="file:///home/runj/Documents/mujoco-3.2.7/model/ant_robot/ant_robot_leftFinger_visible_vis_1.dae" />
            </geometry>
            <material name="leftFinger_visible_material">
                <color rgba="0.460000 0.460000 0.460000 1.0" />
            </material>
        </visual>
        <visual name="rightFinger_visible">
            <origin xyz="-1.168081 -0.178933 0.084196" rpy="-0.698131 3.141593 -1.570797" />
            <geometry>
                <mesh filename="file:///home/runj/Documents/mujoco-3.2.7/model/ant_robot/ant_robot_rightFinger_visible_vis_1.dae" />
            </geometry>
            <material name="rightFinger_visible_material">
                <color rgba="0.460000 0.460000 0.460000 1.0" />
            </material>
        </visual>
    </link>
    <joint type="continuous" name="Body_joint">
        <axis xyz="0 0 1" />
        <parent link="robot_base" />
        <child link="Bottom" />
        <origin xyz="-1.474360 -0.134746 0.125001" rpy="-1.570798 3.141583 3.054325" />
    </joint>
    <link name="Bottom">
        <inertial>
            <origin rpy="-1.570797 2.500451 -1.570796" xyz="-0.230605 -0.000004 0.000000" />
            <inertia izz="5.8778560341191e-06" iyy="6.6221420104302e-05" ixx="6.6221420104015e-05" iyz="3.5358726816156e-11" ixz="-1.3634570667995e-10" ixy="7.9893021225035e-17" />
            <mass value="0.0049999998882413" />
        </inertial>
        <collision name="Bottom">
            <origin xyz="-0.200000 0.000000 -0.000000" rpy="1.570796 3.141593 -1.570792" />
            <geometry>
                <cylinder radius="0.050000000745058" length="0.34999999403954" />
            </geometry>
        </collision>
        <collision name="Bottom">
            <origin xyz="-0.374975 -0.000023 0.000001" rpy="-1.570793 3.817891 -1.570804" />
            <geometry>
                <sphere radius="0.050000000745058" />
            </geometry>
        </collision>
        <collision name="Bottom">
            <origin xyz="-0.324975 -0.000023 0.000001" rpy="-1.570797 2.465294 1.570795" />
            <geometry>
                <cylinder radius="0.025000000372529" length="0.050000000745058" />
            </geometry>
        </collision>
        <visual name="Bottom">
            <origin xyz="-0.200000 0.000000 -0.000000" rpy="1.570796 3.141593 -1.570792" />
            <geometry>
                <cylinder radius="0.050000000745058" length="0.34999999403954" />
            </geometry>
            <material name="Bottom_material">
                <color rgba="0.710000 0.000000 0.000000 1.0" />
            </material>
        </visual>
        <visual name="Bottom">
            <origin xyz="-0.374975 -0.000023 0.000001" rpy="-1.570793 3.817891 -1.570804" />
            <geometry>
                <sphere radius="0.050000000745058" />
            </geometry>
            <material name="Bottom_material">
                <color rgba="0.710000 0.000000 0.000000 1.0" />
            </material>
        </visual>
        <visual name="Bottom">
            <origin xyz="-0.324975 -0.000023 0.000001" rpy="-1.570797 2.465294 1.570795" />
            <geometry>
                <cylinder radius="0.025000000372529" length="0.050000000745058" />
            </geometry>
            <material name="Bottom_material">
                <color rgba="0.850000 0.850000 1.000000 1.0" />
            </material>
        </visual>
    </link>
    <joint type="continuous" name="TL_joint1">
        <axis xyz="0 0 1" />
        <parent link="Bottom" />
        <child link="Coxa" />
        <origin xyz="-0.075000 -0.000001 -0.050000" rpy="-1.570796 1.570796 0.000000" />
    </joint>
    <link name="Coxa">
        <inertial>
            <origin rpy="-3.141593 3.141593 1.570796" xyz="0.000000 0.000000 -0.000000" />
            <inertia izz="9.9359499980111e-07" iyy="1.538464241267e-06" ixx="1.538464241267e-06" iyz="7.7691345506748e-17" ixz="1.1605313728143e-18" ixy="3.0175490704313e-28" />
            <mass value="0.0049999998882413" />
        </inertial>
        <collision name="Coxa">
            <origin xyz="0.000000 0.000000 0.000000" rpy="-3.141593 3.141593 1.570796" />
            <geometry>
                <cylinder radius="0.019999999552965" length="0.050000000745058" />
            </geometry>
        </collision>
        <visual name="Coxa">
            <origin xyz="0.000000 0.000000 0.000000" rpy="-3.141593 3.141593 1.570796" />
            <geometry>
                <cylinder radius="0.019999999552965" length="0.050000000745058" />
            </geometry>
            <material name="Coxa_material">
                <color rgba="0.500000 0.000000 0.000000 1.0" />
            </material>
        </visual>
    </link>
    <joint type="continuous" name="CL_joint1">
        <axis xyz="0 0 1" />
        <parent link="Coxa" />
        <child link="Femur" />
        <origin xyz="0.031000 -0.000000 0.000000" rpy="-1.570820 3.141594 -3.141590" />
    </joint>
    <link name="Femur">
        <inertial>
            <origin rpy="-3.131108 4.712363 3.131107" xyz="0.049996 0.000001 -0.000005" />
            <inertia izz="1.3972430366824e-07" iyy="4.2365280895711e-06" ixx="4.2365280895711e-06" iyz="3.0511016997613e-14" ixz="7.343000434505e-18" ixy="-2.6283264826561e-25" />
            <mass value="0.0049999998882413" />
        </inertial>
        <collision name="Femur">
            <origin xyz="0.049996 0.000001 -0.000005" rpy="-3.131108 4.712363 3.131107" />
            <geometry>
                <cylinder radius="0.0074999998323619" length="0.099999994039536" />
            </geometry>
        </collision>
        <visual name="Femur">
            <origin xyz="0.049996 0.000001 -0.000005" rpy="-3.131108 4.712363 3.131107" />
            <geometry>
                <cylinder radius="0.0074999998323619" length="0.099999994039536" />
            </geometry>
            <material name="Femur_material">
                <color rgba="0.800000 0.000000 0.000000 1.0" />
            </material>
        </visual>
    </link>
    <joint type="continuous" name="FL_joint1">
        <axis xyz="0 0 1" />
        <parent link="Femur" />
        <child link="Tibia" />
        <origin xyz="0.100001 -0.000001 -0.000000" rpy="3.141592 3.141592 3.141591" />
    </joint>
    <link name="Tibia">
        <inertial>
            <origin rpy="1.392270 1.869027 -1.727240" xyz="0.102320 0.000006 -0.000005" />
            <inertia izz="1.3346493286781e-05" iyy="1.6364807642002e-06" ixx="1.2045488299944e-05" iyz="-7.2888872903507e-07" ixz="2.4646314102747e-07" ixy="3.9774151838564e-06" />
            <mass value="0.0049999998882413" />
        </inertial>
        <collision name="Tibia">
            <origin xyz="0.075016 0.000006 -0.000005" rpy="-3.096728 4.712254 3.096729" />
            <geometry>
                <cylinder radius="0.0074999998323619" length="0.15000000596046" />
            </geometry>
        </collision>
        <collision name="Tibia">
            <origin xyz="0.154013 0.000006 -0.000005" rpy="-2.161445 4.712251 0.590646" />
            <geometry>
                <sphere radius="0.014999999664724" />
            </geometry>
        </collision>
        <visual name="Tibia">
            <origin xyz="0.075016 0.000006 -0.000005" rpy="-3.096728 4.712254 3.096729" />
            <geometry>
                <cylinder radius="0.0074999998323619" length="0.15000000596046" />
            </geometry>
            <material name="Tibia_material">
                <color rgba="0.800000 0.000000 0.000000 1.0" />
            </material>
        </visual>
        <visual name="Tibia">
            <origin xyz="0.154013 0.000006 -0.000005" rpy="-2.161445 4.712251 0.590646" />
            <geometry>
                <sphere radius="0.014999999664724" />
            </geometry>
            <material name="Tibia_material">
                <color rgba="0.500000 0.000000 0.000000 1.0" />
            </material>
        </visual>
    </link>
    <joint type="continuous" name="TL_joint2">
        <axis xyz="0 0 1" />
        <parent link="Bottom" />
        <child link="Coxa_2" />
        <origin xyz="-0.324968 -0.000017 -0.050000" rpy="-1.570795 1.570796 0.000000" />
    </joint>
    <link name="Coxa_2">
        <inertial>
            <origin rpy="-3.141593 3.141593 1.570796" xyz="0.000000 0.000000 -0.000000" />
            <inertia izz="9.9359499980111e-07" iyy="1.538464241267e-06" ixx="1.538464241267e-06" iyz="7.7691345506748e-17" ixz="1.1605313728143e-18" ixy="3.0175490704313e-28" />
            <mass value="0.0049999998882413" />
        </inertial>
        <collision name="Coxa">
            <origin xyz="0.000000 0.000000 0.000000" rpy="-3.141593 3.141593 1.570796" />
            <geometry>
                <cylinder radius="0.019999999552965" length="0.050000000745058" />
            </geometry>
        </collision>
        <visual name="Coxa">
            <origin xyz="0.000000 0.000000 0.000000" rpy="-3.141593 3.141593 1.570796" />
            <geometry>
                <cylinder radius="0.019999999552965" length="0.050000000745058" />
            </geometry>
            <material name="Coxa_2_material">
                <color rgba="0.500000 0.000000 0.000000 1.0" />
            </material>
        </visual>
    </link>
    <joint type="continuous" name="CL_joint2">
        <axis xyz="0 0 1" />
        <parent link="Coxa_2" />
        <child link="Femur_2" />
        <origin xyz="0.031000 -0.000000 0.000000" rpy="-1.570820 3.141594 -3.141590" />
    </joint>
    <link name="Femur_2">
        <inertial>
            <origin rpy="-3.131108 4.712363 3.131107" xyz="0.049996 0.000001 -0.000005" />
            <inertia izz="1.3972430366824e-07" iyy="4.2365280895711e-06" ixx="4.2365280895711e-06" iyz="3.0511016997613e-14" ixz="7.343000434505e-18" ixy="-2.6283264826561e-25" />
            <mass value="0.0049999998882413" />
        </inertial>
        <collision name="Femur">
            <origin xyz="0.049996 0.000001 -0.000005" rpy="-3.131108 4.712363 3.131107" />
            <geometry>
                <cylinder radius="0.0074999998323619" length="0.099999994039536" />
            </geometry>
        </collision>
        <visual name="Femur">
            <origin xyz="0.049996 0.000001 -0.000005" rpy="-3.131108 4.712363 3.131107" />
            <geometry>
                <cylinder radius="0.0074999998323619" length="0.099999994039536" />
            </geometry>
            <material name="Femur_2_material">
                <color rgba="0.800000 0.000000 0.000000 1.0" />
            </material>
        </visual>
    </link>
    <joint type="continuous" name="FL_joint2">
        <axis xyz="0 0 1" />
        <parent link="Femur_2" />
        <child link="Tibia_2" />
        <origin xyz="0.100001 -0.000001 -0.000000" rpy="3.141592 3.141592 3.141591" />
    </joint>
    <link name="Tibia_2">
        <inertial>
            <origin rpy="1.391767 1.869027 -1.727241" xyz="0.102321 0.000006 -0.000004" />
            <inertia izz="1.3345140633848e-05" iyy="1.6300193173605e-06" ixx="1.2053302763515e-05" iyz="-7.399159479264e-07" ixz="2.4939934318579e-07" ixy="3.9669414798638e-06" />
            <mass value="0.0049999998882413" />
        </inertial>
        <collision name="Tibia">
            <origin xyz="0.075016 0.000006 -0.000004" rpy="-3.097606 4.712254 3.097607" />
            <geometry>
                <cylinder radius="0.0074999998323619" length="0.15000000596046" />
            </geometry>
        </collision>
        <collision name="Tibia">
            <origin xyz="0.154014 0.000005 -0.000004" rpy="-2.160708 4.712251 0.589909" />
            <geometry>
                <sphere radius="0.014999999664724" />
            </geometry>
        </collision>
        <visual name="Tibia">
            <origin xyz="0.075016 0.000006 -0.000004" rpy="-3.097606 4.712254 3.097607" />
            <geometry>
                <cylinder radius="0.0074999998323619" length="0.15000000596046" />
            </geometry>
            <material name="Tibia_2_material">
                <color rgba="0.800000 0.000000 0.000000 1.0" />
            </material>
        </visual>
        <visual name="Tibia">
            <origin xyz="0.154014 0.000005 -0.000004" rpy="-2.160708 4.712251 0.589909" />
            <geometry>
                <sphere radius="0.014999999664724" />
            </geometry>
            <material name="Tibia_2_material">
                <color rgba="0.500000 0.000000 0.000000 1.0" />
            </material>
        </visual>
    </link>
    <joint type="continuous" name="TR_joint1">
        <axis xyz="0 0 1" />
        <parent link="Bottom" />
        <child link="Coxa_3" />
        <origin xyz="-0.075000 -0.000003 0.050001" rpy="1.570796 1.570796 0.000000" />
    </joint>
    <link name="Coxa_3">
        <inertial>
            <origin rpy="-0.000001 3.141593 1.570796" xyz="-0.000000 0.000000 0.000000" />
            <inertia izz="9.9359499980111e-07" iyy="1.538464241267e-06" ixx="1.538464241267e-06" iyz="7.7691345506748e-17" ixz="1.1605313728143e-18" ixy="3.0175490704313e-28" />
            <mass value="0.0049999998882413" />
        </inertial>
        <collision name="Coxa">
            <origin xyz="0.000000 0.000000 0.000000" rpy="-0.000001 3.141593 1.570796" />
            <geometry>
                <cylinder radius="0.019999999552965" length="0.050000000745058" />
            </geometry>
        </collision>
        <visual name="Coxa">
            <origin xyz="0.000000 0.000000 0.000000" rpy="-0.000001 3.141593 1.570796" />
            <geometry>
                <cylinder radius="0.019999999552965" length="0.050000000745058" />
            </geometry>
            <material name="Coxa_3_material">
                <color rgba="0.500000 0.000000 0.000000 1.0" />
            </material>
        </visual>
    </link>
    <joint type="continuous" name="CR_joint1">
        <axis xyz="0 0 1" />
        <parent link="Coxa_3" />
        <child link="Femur_3" />
        <origin xyz="-0.031000 -0.000000 0.000000" rpy="1.570773 3.141592 -0.000002" />
    </joint>
    <link name="Femur_3">
        <inertial>
            <origin rpy="-3.131108 4.712363 3.131107" xyz="0.049996 0.000001 -0.000005" />
            <inertia izz="1.3972430366824e-07" iyy="4.2365280895711e-06" ixx="4.2365280895711e-06" iyz="3.0511016997613e-14" ixz="7.343000434505e-18" ixy="-2.6283264826561e-25" />
            <mass value="0.0049999998882413" />
        </inertial>
        <collision name="Femur">
            <origin xyz="0.049996 0.000001 -0.000005" rpy="-3.131108 4.712363 3.131107" />
            <geometry>
                <cylinder radius="0.0074999998323619" length="0.099999994039536" />
            </geometry>
        </collision>
        <visual name="Femur">
            <origin xyz="0.049996 0.000001 -0.000005" rpy="-3.131108 4.712363 3.131107" />
            <geometry>
                <cylinder radius="0.0074999998323619" length="0.099999994039536" />
            </geometry>
            <material name="Femur_3_material">
                <color rgba="0.800000 0.000000 0.000000 1.0" />
            </material>
        </visual>
    </link>
    <joint type="continuous" name="FR_joint1">
        <axis xyz="0 0 1" />
        <parent link="Femur_3" />
        <child link="Tibia_3" />
        <origin xyz="0.100001 -0.000001 -0.000000" rpy="3.141592 3.141592 3.141591" />
    </joint>
    <link name="Tibia_3">
        <inertial>
            <origin rpy="1.570513 2.061631 1.570548" xyz="0.104039 0.000007 -0.000004" />
            <inertia izz="2.4547644884974e-07" iyy="1.4307468328892e-05" ixx="1.4307963964898e-05" iyz="5.1311191339726e-10" ixz="2.0708528835157e-09" ixy="-1.3951477201398e-12" />
            <mass value="0.0049999998882413" />
        </inertial>
        <collision name="Tibia">
            <origin xyz="0.075016 0.000006 -0.000004" rpy="-3.096748 4.712254 3.096749" />
            <geometry>
                <cylinder radius="0.0074999998323619" length="0.15000000596046" />
            </geometry>
        </collision>
        <collision name="Tibia">
            <origin xyz="0.158985 0.000008 -0.000004" rpy="1.317707 1.570915 2.888506" />
            <geometry>
                <sphere radius="0.014999999664724" />
            </geometry>
        </collision>
        <visual name="Tibia">
            <origin xyz="0.075016 0.000006 -0.000004" rpy="-3.096748 4.712254 3.096749" />
            <geometry>
                <cylinder radius="0.0074999998323619" length="0.15000000596046" />
            </geometry>
            <material name="Tibia_3_material">
                <color rgba="0.800000 0.000000 0.000000 1.0" />
            </material>
        </visual>
        <visual name="Tibia">
            <origin xyz="0.158985 0.000008 -0.000004" rpy="1.317707 1.570915 2.888506" />
            <geometry>
                <sphere radius="0.014999999664724" />
            </geometry>
            <material name="Tibia_3_material">
                <color rgba="0.500000 0.000000 0.000000 1.0" />
            </material>
        </visual>
    </link>
    <joint type="continuous" name="TR_joint2">
        <axis xyz="0 0 1" />
        <parent link="Bottom" />
        <child link="Coxa_4" />
        <origin xyz="-0.324965 -0.000021 0.050001" rpy="-3.089770 1.570799 1.622620" />
    </joint>
    <link name="Coxa_4">
        <inertial>
            <origin rpy="-0.000001 3.141593 1.570796" xyz="-0.000000 0.000000 0.000000" />
            <inertia izz="9.9359499980111e-07" iyy="1.538464241267e-06" ixx="1.538464241267e-06" iyz="7.7691345506748e-17" ixz="1.1605313728143e-18" ixy="3.0175490704313e-28" />
            <mass value="0.0049999998882413" />
        </inertial>
        <collision name="Coxa">
            <origin xyz="0.000000 0.000000 0.000000" rpy="-0.000001 3.141593 1.570796" />
            <geometry>
                <cylinder radius="0.019999999552965" length="0.050000000745058" />
            </geometry>
        </collision>
        <visual name="Coxa">
            <origin xyz="0.000000 0.000000 0.000000" rpy="-0.000001 3.141593 1.570796" />
            <geometry>
                <cylinder radius="0.019999999552965" length="0.050000000745058" />
            </geometry>
            <material name="Coxa_4_material">
                <color rgba="0.500000 0.000000 0.000000 1.0" />
            </material>
        </visual>
    </link>
    <joint type="continuous" name="CR_joint2">
        <axis xyz="0 0 1" />
        <parent link="Coxa_4" />
        <child link="Femur_4" />
        <origin xyz="-0.031000 -0.000000 0.000000" rpy="1.570773 3.141592 -0.000002" />
    </joint>
    <link name="Femur_4">
        <inertial>
            <origin rpy="-3.131108 4.712363 3.131107" xyz="0.049996 0.000001 -0.000005" />
            <inertia izz="1.3972430366824e-07" iyy="4.2365280895711e-06" ixx="4.2365280895711e-06" iyz="3.0511016997613e-14" ixz="7.343000434505e-18" ixy="-2.6283264826561e-25" />
            <mass value="0.0049999998882413" />
        </inertial>
        <collision name="Femur">
            <origin xyz="0.049996 0.000001 -0.000005" rpy="-3.131108 4.712363 3.131107" />
            <geometry>
                <cylinder radius="0.0074999998323619" length="0.099999994039536" />
            </geometry>
        </collision>
        <visual name="Femur">
            <origin xyz="0.049996 0.000001 -0.000005" rpy="-3.131108 4.712363 3.131107" />
            <geometry>
                <cylinder radius="0.0074999998323619" length="0.099999994039536" />
            </geometry>
            <material name="Femur_4_material">
                <color rgba="0.800000 0.000000 0.000000 1.0" />
            </material>
        </visual>
    </link>
    <joint type="continuous" name="FR_joint2">
        <axis xyz="0 0 1" />
        <parent link="Femur_4" />
        <child link="Tibia_4" />
        <origin xyz="0.100001 -0.000001 -0.000000" rpy="3.141592 3.141592 3.141591" />
    </joint>
    <link name="Tibia_4">
        <inertial>
            <origin rpy="1.570946 3.632450 -1.570867" xyz="0.104039 0.000007 -0.000004" />
            <inertia izz="2.4547592650998e-07" iyy="1.4307965430683e-05" ixx="1.4307475279861e-05" iyz="2.1557911358413e-10" ixz="8.6079063805682e-10" ixy="1.3020356006122e-12" />
            <mass value="0.0049999998882413" />
        </inertial>
        <collision name="Tibia">
            <origin xyz="0.075016 0.000006 -0.000005" rpy="-3.096573 4.712254 3.096574" />
            <geometry>
                <cylinder radius="0.0074999998323619" length="0.15000000596046" />
            </geometry>
        </collision>
        <collision name="Tibia">
            <origin xyz="0.158985 0.000008 -0.000004" rpy="1.318311 1.570915 2.889109" />
            <geometry>
                <sphere radius="0.014999999664724" />
            </geometry>
        </collision>
        <visual name="Tibia">
            <origin xyz="0.075016 0.000006 -0.000005" rpy="-3.096573 4.712254 3.096574" />
            <geometry>
                <cylinder radius="0.0074999998323619" length="0.15000000596046" />
            </geometry>
            <material name="Tibia_4_material">
                <color rgba="0.800000 0.000000 0.000000 1.0" />
            </material>
        </visual>
        <visual name="Tibia">
            <origin xyz="0.158985 0.000008 -0.000004" rpy="1.318311 1.570915 2.889109" />
            <geometry>
                <sphere radius="0.014999999664724" />
            </geometry>
            <material name="Tibia_4_material">
                <color rgba="0.500000 0.000000 0.000000 1.0" />
            </material>
        </visual>
    </link>
    <joint type="continuous" name="TL_joint0">
        <axis xyz="0 0 1" />
        <parent link="robot_base" />
        <child link="Coxa_5" />
        <origin xyz="-1.295639 -0.100191 0.124977" rpy="-3.141583 3.141591 -1.658064" />
    </joint>
    <link name="Coxa_5">
        <inertial>
            <origin rpy="-3.141593 3.141593 1.570796" xyz="0.000000 0.000000 -0.000000" />
            <inertia izz="9.9359499980111e-07" iyy="1.538464241267e-06" ixx="1.538464241267e-06" iyz="7.7691345506748e-17" ixz="1.1605313728143e-18" ixy="3.0175490704313e-28" />
            <mass value="0.0049999998882413" />
        </inertial>
        <collision name="Coxa">
            <origin xyz="0.000000 0.000000 0.000000" rpy="-3.141593 3.141593 1.570796" />
            <geometry>
                <cylinder radius="0.019999999552965" length="0.050000000745058" />
            </geometry>
        </collision>
        <visual name="Coxa">
            <origin xyz="0.000000 0.000000 0.000000" rpy="-3.141593 3.141593 1.570796" />
            <geometry>
                <cylinder radius="0.019999999552965" length="0.050000000745058" />
            </geometry>
            <material name="Coxa_5_material">
                <color rgba="0.600000 0.000000 0.000000 1.0" />
            </material>
        </visual>
    </link>
    <joint type="continuous" name="CL_joint0">
        <axis xyz="0 0 1" />
        <parent link="Coxa_5" />
        <child link="Femur_5" />
        <origin xyz="0.031000 -0.000000 0.000000" rpy="-1.570820 3.141594 -3.141590" />
    </joint>
    <link name="Femur_5">
        <inertial>
            <origin rpy="-3.131108 4.712363 3.131107" xyz="0.049996 0.000001 -0.000005" />
            <inertia izz="1.3972430366824e-07" iyy="4.2365280895711e-06" ixx="4.2365280895711e-06" iyz="3.0511016997613e-14" ixz="7.343000434505e-18" ixy="-2.6283264826561e-25" />
            <mass value="0.0049999998882413" />
        </inertial>
        <collision name="Femur">
            <origin xyz="0.049996 0.000001 -0.000005" rpy="-3.131108 4.712363 3.131107" />
            <geometry>
                <cylinder radius="0.0074999998323619" length="0.099999994039536" />
            </geometry>
        </collision>
        <visual name="Femur">
            <origin xyz="0.049996 0.000001 -0.000005" rpy="-3.131108 4.712363 3.131107" />
            <geometry>
                <cylinder radius="0.0074999998323619" length="0.099999994039536" />
            </geometry>
            <material name="Femur_5_material">
                <color rgba="0.800000 0.000000 0.000000 1.0" />
            </material>
        </visual>
    </link>
    <joint type="continuous" name="FL_joint0">
        <axis xyz="0 0 1" />
        <parent link="Femur_5" />
        <child link="Tibia_5" />
        <origin xyz="0.100001 -0.000001 -0.000000" rpy="3.141592 3.141592 3.141591" />
    </joint>
    <link name="Tibia_5">
        <inertial>
            <origin rpy="1.392273 1.869027 -1.727237" xyz="0.102322 0.000006 0.000001" />
            <inertia izz="1.3346233969624e-05" iyy="1.631588432563e-06" ixx="1.2049967377421e-05" iyz="-7.2840923733208e-07" ixz="2.4581218802597e-07" ixy="3.9710618910685e-06" />
            <mass value="0.0049999998882413" />
        </inertial>
        <collision name="Tibia">
            <origin xyz="0.075018 0.000006 -0.000005" rpy="-3.126854 4.712259 3.126855" />
            <geometry>
                <cylinder radius="0.0074999998323619" length="0.15000000596046" />
            </geometry>
        </collision>
        <collision name="Tibia">
            <origin xyz="0.154014 0.000006 0.000012" rpy="-2.164582 4.712251 0.593783" />
            <geometry>
                <sphere radius="0.014999999664724" />
            </geometry>
        </collision>
        <visual name="Tibia">
            <origin xyz="0.075018 0.000006 -0.000005" rpy="-3.126854 4.712259 3.126855" />
            <geometry>
                <cylinder radius="0.0074999998323619" length="0.15000000596046" />
            </geometry>
            <material name="Tibia_5_material">
                <color rgba="0.800000 0.000000 0.000000 1.0" />
            </material>
        </visual>
        <visual name="Tibia">
            <origin xyz="0.154014 0.000006 0.000012" rpy="-2.164582 4.712251 0.593783" />
            <geometry>
                <sphere radius="0.014999999664724" />
            </geometry>
            <material name="Tibia_5_material">
                <color rgba="0.500000 0.000000 0.000000 1.0" />
            </material>
        </visual>
    </link>
    <joint type="continuous" name="TR_joint0">
        <axis xyz="0 0 1" />
        <parent link="robot_base" />
        <child link="Coxa_6" />
        <origin xyz="-1.304355 -0.199811 0.124973" rpy="0.000008 3.141589 -1.658064" />
    </joint>
    <link name="Coxa_6">
        <inertial>
            <origin rpy="-0.000001 3.141593 1.570796" xyz="-0.000000 0.000000 0.000000" />
            <inertia izz="9.9359499980111e-07" iyy="1.538464241267e-06" ixx="1.538464241267e-06" iyz="7.7691345506748e-17" ixz="1.1605313728143e-18" ixy="3.0175490704313e-28" />
            <mass value="0.0049999998882413" />
        </inertial>
        <collision name="Coxa">
            <origin xyz="0.000000 0.000000 0.000000" rpy="-0.000001 3.141593 1.570796" />
            <geometry>
                <cylinder radius="0.019999999552965" length="0.050000000745058" />
            </geometry>
        </collision>
        <visual name="Coxa">
            <origin xyz="0.000000 0.000000 0.000000" rpy="-0.000001 3.141593 1.570796" />
            <geometry>
                <cylinder radius="0.019999999552965" length="0.050000000745058" />
            </geometry>
            <material name="Coxa_6_material">
                <color rgba="0.500000 0.000000 0.000000 1.0" />
            </material>
        </visual>
    </link>
    <joint type="continuous" name="CR_joint0">
        <axis xyz="0 0 1" />
        <parent link="Coxa_6" />
        <child link="Femur_6" />
        <origin xyz="-0.031000 -0.000000 0.000000" rpy="1.570773 3.141592 -0.000002" />
    </joint>
    <link name="Femur_6">
        <inertial>
            <origin rpy="-3.131108 4.712363 3.131107" xyz="0.049996 0.000001 -0.000005" />
            <inertia izz="1.3972430366824e-07" iyy="4.2365280895711e-06" ixx="4.2365280895711e-06" iyz="3.0511016997613e-14" ixz="7.343000434505e-18" ixy="-2.6283264826561e-25" />
            <mass value="0.0049999998882413" />
        </inertial>
        <collision name="Femur">
            <origin xyz="0.049996 0.000001 -0.000005" rpy="-3.131108 4.712363 3.131107" />
            <geometry>
                <cylinder radius="0.0074999998323619" length="0.099999994039536" />
            </geometry>
        </collision>
        <visual name="Femur">
            <origin xyz="0.049996 0.000001 -0.000005" rpy="-3.131108 4.712363 3.131107" />
            <geometry>
                <cylinder radius="0.0074999998323619" length="0.099999994039536" />
            </geometry>
            <material name="Femur_6_material">
                <color rgba="0.800000 0.000000 0.000000 1.0" />
            </material>
        </visual>
    </link>
    <joint type="continuous" name="FR_joint0">
        <axis xyz="0 0 1" />
        <parent link="Femur_6" />
        <child link="Tibia_6" />
        <origin xyz="0.100001 -0.000001 -0.000000" rpy="3.141592 3.141592 3.141591" />
    </joint>
    <link name="Tibia_6">
        <inertial>
            <origin rpy="-1.570639 3.632444 -1.570868" xyz="0.104038 0.000007 -0.000007" />
            <inertia izz="2.4547643806814e-07" iyy="1.4307946802609e-05" ixx="1.4307453196712e-05" iyz="1.3380044789538e-10" ixz="-5.3802719927801e-10" ixy="-1.8780330936647e-12" />
            <mass value="0.0049999998882413" />
        </inertial>
        <collision name="Tibia">
            <origin xyz="0.075015 0.000006 -0.000004" rpy="-3.096097 4.712254 3.096098" />
            <geometry>
                <cylinder radius="0.0074999998323619" length="0.15000000596046" />
            </geometry>
        </collision>
        <collision name="Tibia">
            <origin xyz="0.158985 0.000008 -0.000011" rpy="1.317856 1.570915 2.888655" />
            <geometry>
                <sphere radius="0.014999999664724" />
            </geometry>
        </collision>
        <visual name="Tibia">
            <origin xyz="0.075015 0.000006 -0.000004" rpy="-3.096097 4.712254 3.096098" />
            <geometry>
                <cylinder radius="0.0074999998323619" length="0.15000000596046" />
            </geometry>
            <material name="Tibia_6_material">
                <color rgba="0.800000 0.000000 0.000000 1.0" />
            </material>
        </visual>
        <visual name="Tibia">
            <origin xyz="0.158985 0.000008 -0.000011" rpy="1.317856 1.570915 2.888655" />
            <geometry>
                <sphere radius="0.014999999664724" />
            </geometry>
            <material name="Tibia_6_material">
                <color rgba="0.500000 0.000000 0.000000 1.0" />
            </material>
        </visual>
    </link>
</robot>
